Workbook

Sheet DASHBOARD
B2: VILLA CONSTRUCTION - EXECUTIVE DASHBOARD
B3: Hyderabad Telangana | 50 Villas | Apr 2026 - Sep 2028
B5: CEO VIEW - Project Overview | F5: CFO VIEW - Financial Returns
B7: Total Revenue | C7: =SALES_REVENUE!$D$8 -> 0 | G7: ROI | H7: =CASH_FLOW!$B$19 -> 0
B8: Total Project Cost | C8: =ASSUMPTIONS!$B$59 -> 0 | G8: IRR (XIRR) | H8: =CASH_FLOW!$B$21 -> 0
B9: Net Profit | C9: =CASH_FLOW!$B$18 -> 0 | G9: MOIC | H9: =CASH_FLOW!$B$20 -> 0
B10: Gross Margin % | C10: =CASH_FLOW!$B$18/SALES_REVENUE!$D$8 -> 0 | G10: NPV | H10: =CASH_FLOW!$B$22 -> 0
B11: Units Sold | C11: =SALES_REVENUE!E8 -> 0 | G11: DSCR | H11: =CASH_FLOW!$B$23 -> 0
B12: Units Remaining | C12: =SALES_REVENUE!B8-SALES_REVENUE!E8 -> 0 | G12: LTV | H12: =CASH_FLOW!$B$24 -> 0
B14: TARGET vs ACTUAL
B15: Metric | C15: Target | D15: Actual | E15: Status
B16: ROI | C16: =ASSUMPTIONS!$B$54 -> 0 | D16: =CASH_FLOW!$B$19 -> 0 | E16: =IF(D16>=C16,"On Track","Below Target") -> 0
B17: IRR | C17: =ASSUMPTIONS!$B$55 -> 0 | D17: =CASH_FLOW!$B$21 -> 0 | E17: =IF(D17>=C17,"On Track","Below Target") -> 0
B18: MOIC | C18: =ASSUMPTIONS!$B$56 -> 0 | D18: =CASH_FLOW!$B$20 -> 0 | E18: =IF(D18>=C18,"On Track","Below Target") -> 0

Sheet ASSUMPTIONS
A1: VILLA CONSTRUCTION PROJECT - ASSUMPTIONS
A2: Hyderabad, Telangana | 50 Villas x 3 Floors | Apr 2026 - Sep 2028 | D2: Yellow = Input | Blue = Calculated
A4: PROJECT PARAMETERS
A5: Number of Villas | B5: 50
A6: Floors per Villa | B6: 3
A7: Built-up Area per Villa (sq.ft) | B7: 2100
A8: Total Built-up Area (sq.ft) | B8: =ASSUMPTIONS!$B$5*ASSUMPTIONS!$B$7 -> 0
A9: Project Start Date | B9: 46113
A10: Project End Date | B10: 47026
A11: Project Duration (months) | B11: 30
A12: LAND & SITE
A13: Land Acquisition Cost (INR) | B13: 50000000
A14: CONSTRUCTION COSTS
A15: Construction Cost per sq.ft (INR) | B15: 2800
A16: Total Construction Cost (INR) | B16: =ASSUMPTIONS!$B$8*ASSUMPTIONS!$B$15 -> 0
A17: Contingency (% of Construction) | B17: 0.05
A18: Contingency Amount (INR) | B18: =ASSUMPTIONS!$B$16*ASSUMPTIONS!$B$17 -> 0
A19: PERMITS & APPROVALS
A20: Permits as % of Total Project Cost | B20: 0.05
A21: Permit Cost (INR) - see PERMITS tab | B21: =PERMITS!$B$21 -> 0
A22: SALES & PRICING
A23: Sale Price - Low (INR/villa) | B23: 7000000
A24: Sale Price - High (INR/villa) | B24: 11000000
A25: Average Sale Price (INR/villa) | B25: =AVERAGE(ASSUMPTIONS!$B$23:ASSUMPTIONS!$B$24) -> 0
A26: UNIT MIX
A27: Villa Type | B27: Units | C27: Price (INR) | D27: Revenue (INR)
A28: 3BHK Standard | B28: 20 | C28: 8000000 | D28: =B28*C28 -> 0
A29: 3BHK Premium | B29: 18 | C29: 10000000 | D29: =B29*C29 -> 0
A30: 4BHK Luxury | B30: 12 | C30: 11500000 | D30: =B30*C30 -> 0
A31: Total | B31: =SUM(B28:B30) -> 0 | D31: =SUM(D28:D30) -> 0
A33: Total Revenue (INR) | B33: =ASSUMPTIONS!$D$31 -> 0 | D33: From unit mix
A34: PAYMENT COLLECTION SCHEDULE
A35: Milestone | B35: % of Price | C35: Timing (Month)
A36: Booking / Token | B36: 0.1 | C36: 1
A37: Agreement | B37: 0.15 | C37: 3
A38: Foundation | B38: 0.15 | C38: 6
A39: Slab 1 | B39: 0.15 | C39: 12
A40: Slab 2 | B40: 0.15 | C40: 18
A41: Finishing | B41: 0.15 | C41: 24
A42: Possession | B42: 0.15 | C42: 30
...

Sheet PERMITS
A1: PERMITS & APPROVALS TRACKER - Hyderabad / Telangana
A3: Permit / Approval | B3: Budget (INR) | C3: Actual (INR) | D3: Variance (INR) | E3: Status | F3: Applied Date | G3: Approved Date
A4: GHMC Building Permission | B4: 2500000 | C4: 0 | D4: =C4-B4 -> 0 | E4: Pending | F4: 46127
A5: RERA Registration | B5: 500000 | C5: 0 | D5: =C5-B5 -> 0 | E5: Pending | F5: 46143
A6: Fire NOC | B6: 350000 | C6: 0 | D6: =C6-B6 -> 0 | E6: Pending | F6: 46235
A7: Electricity (TSSPDCL) - LT Connection | B7: 800000 | C7: 0 | D7: =C7-B7 -> 0 | E7: Pending | F7: 46174
A8: Electricity - HT Line Extension | B8: 1200000 | C8: 0 | D8: =C8-B8 -> 0 | E8: Pending | F8: 46204
A9: Electricity - Transformer Sub-station | B9: 2500000 | C9: 0 | D9: =C9-B9 -> 0 | E9: Pending | F9: 46266
A10: Water (HMWSSB) Connection | B10: 600000 | C10: 0 | D10: =C10-B10 -> 0 | E10: Pending | F10: 46188
A11: Environmental Clearance | B11: 400000 | C11: 0 | D11: =C11-B11 -> 0 | E11: Pending | F11: 46157
A12: Airport Authority NOC (if applicable) | B12: 200000 | C12: 0 | D12: =C12-B12 -> 0 | E12: N/A
A13: Labour License / BOCW | B13: 150000 | C13: 0 | D13: =C13-B13 -> 0 | E13: Pending | F13: 46113
A15: TOTAL PERMIT COST | B15: =SUM(B4:B13) -> 0 | C15: =SUM(C4:C13) -> 0 | D15: =C15-B15 -> 0

Sheet SOV_CONSTRUCTION
A1: SCHEDULE OF VALUES - CONSTRUCTION (Trade-wise Budget)
A3: Trade / Work Package | B3: Budget (INR) | C3: % of Const. | D3: Planned Start | E3: Planned End | F3: Status
A4: Site Development & Earthwork | B4: =ASSUMPTIONS!$B$16*0.04 -> 0 | C4: 0.04 | D4: 46113 | E4: 46203 | F4: Planned
A5: RCC Structure (Foundation to Slab) | B5: =ASSUMPTIONS!$B$16*0.28 -> 0 | C5: 0.28 | D5: 46143 | E5: 46568 | F5: Planned
A6: Masonry & Plastering | B6: =ASSUMPTIONS!$B$16*0.12 -> 0 | C6: 0.12 | D6: 46296 | E6: 46752 | F6: Planned
A7: Electrical (Internal + External) | B7: =ASSUMPTIONS!$B$16*0.1 -> 0 | C7: 0.1 | D7: 46388 | E7: 46934 | F7: Planned
A8: Plumbing & Sanitary | B8: =ASSUMPTIONS!$B$16*0.08 -> 0 | C8: 0.08 | D8: 46388 | E8: 46843 | F8: Planned
A9: Flooring & Tiling | B9: =ASSUMPTIONS!$B$16*0.09 -> 0 | C9: 0.09 | D9: 46569 | E9: 46934 | F9: Planned
A10: Doors, Windows & Aluminium | B10: =ASSUMPTIONS!$B$16*0.07 -> 0 | C10: 0.07 | D10: 46478 | E10: 46904 | F10: Planned
A11: Painting (Internal + External) | B11: =ASSUMPTIONS!$B$16*0.05 -> 0 | C11: 0.05 | D11: 46753 | E11: 46996 | F11: Planned
A12: HVAC / VRF (if applicable) | B12: =ASSUMPTIONS!$B$16*0.04 -> 0 | C12: 0.04 | D12: 46784 | E12: 46965 | F12: Planned
A13: Landscaping & External Works | B13: =ASSUMPTIONS!$B$16*0.05 -> 0 | C13: 0.05 | D13: 46844 | E13: 47026 | F13: Planned
A14: Elevator / Lift (if applicable) | B14: =ASSUMPTIONS!$B$16*0.03 -> 0 | C14: 0.03 | D14: 46661 | E14: 46934 | F14: Planned
A15: Miscellaneous & Finishing | B15: =ASSUMPTIONS!$B$16*0.05 -> 0 | C15: 0.05 | D15: 46813 | E15: 47026 | F15: Planned
A17: TOTAL SOV | B17: =SUM(B4:B15) -> 0

Sheet SALES_REVENUE
A1: SALES & REVENUE - Unit Mix & Payment Collection
A3: UNIT MIX
A4: Villa Type | B4: Units | C4: Price (INR) | D4: Revenue (INR) | E4: Sold | F4: Unsold | G4: % Sold
A5: =ASSUMPTIONS!A29 -> 0 | B5: =ASSUMPTIONS!B29 -> 0 | C5: =ASSUMPTIONS!C29 -> 0 | D5: =ASSUMPTIONS!D29 -> 0 | E5: 0 | F5: =B5-E5 -> 0 | G5: =IF(B5=0,0,E5/B5) -> 0
A6: =ASSUMPTIONS!A30 -> 0 | B6: =ASSUMPTIONS!B30 -> 0 | C6: =ASSUMPTIONS!C30 -> 0 | D6: =ASSUMPTIONS!D30 -> 0 | E6: 0 | F6: =B6-E6 -> 0 | G6: =IF(B6=0,0,E6/B6) -> 0
A7: =ASSUMPTIONS!A31 -> 0 | B7: =ASSUMPTIONS!B31 -> 0 | C7: =ASSUMPTIONS!C31 -> 0 | D7: =ASSUMPTIONS!D31 -> 0 | E7: 0 | F7: =B7-E7 -> 0 | G7: =IF(B7=0,0,E7/B7) -> 0
A8: TOTAL | B8: =SUM(B5:B7) -> 0 | D8: =SUM(D5:D7) -> 0 | E8: =SUM(E5:E7) -> 0
A10: PAYMENT COLLECTION BY QUARTER
A11: Quarter | B11: Period | C11: Booking | D11: Construction-Linked | E11: Possession | F11: Total Collections | G11: Cumulative
A12: Q1 FY27 | B12: Apr-Jun 2026 | C12: =SALES_REVENUE!$D$8*0.1*0.25 -> 0 | D12: =SALES_REVENUE!$D$8*0.1*0.60 -> 0 | E12: =SALES_REVENUE!$D$8*0.1*0.15 -> 0 | F12: =SUM(C12:E12) -> 0 | G12: =F12 -> 0
A13: Q2 FY27 | B13: Jul-Sep 2026 | C13: =SALES_REVENUE!$D$8*0.12*0.25 -> 0 | D13: =SALES_REVENUE!$D$8*0.12*0.60 -> 0 | E13: =SALES_REVENUE!$D$8*0.12*0.15 -> 0 | F13: =SUM(C13:E13) -> 0 | G13: =G12+F13 -> 0
A14: Q3 FY27 | B14: Oct-Dec 2026 | C14: =SALES_REVENUE!$D$8*0.08*0.25 -> 0 | D14: =SALES_REVENUE!$D$8*0.08*0.60 -> 0 | E14: =SALES_REVENUE!$D$8*0.08*0.15 -> 0 | F14: =SUM(C14:E14) -> 0 | G14: =G13+F14 -> 0
A15: Q4 FY27 | B15: Jan-Mar 2027 | C15: =SALES_REVENUE!$D$8*0.1*0.25 -> 0 | D15: =SALES_REVENUE!$D$8*0.1*0.60 -> 0 | E15: =SALES_REVENUE!$D$8*0.1*0.15 -> 0 | F15: =SUM(C15:E15) -> 0 | G15: =G14+F15 -> 0
A16: Q1 FY28 | B16: Apr-Jun 2027 | C16: =SALES_REVENUE!$D$8*0.12*0.25 -> 0 | D16: =SALES_REVENUE!$D$8*0.12*0.60 -> 0 | E16: =SALES_REVENUE!$D$8*0.12*0.15 -> 0 | F16: =SUM(C16:E16) -> 0 | G16: =G15+F16 -> 0
A17: Q2 FY28 | B17: Jul-Sep 2027 | C17: =SALES_REVENUE!$D$8*0.12*0.25 -> 0 | D17: =SALES_REVENUE!$D$8*0.12*0.60 -> 0 | E17: =SALES_REVENUE!$D$8*0.12*0.15 -> 0 | F17: =SUM(C17:E17) -> 0 | G17: =G16+F17 -> 0
A18: Q3 FY28 | B18: Oct-Dec 2027 | C18: =SALES_REVENUE!$D$8*0.1*0.25 -> 0 | D18: =SALES_REVENUE!$D$8*0.1*0.60 -> 0 | E18: =SALES_REVENUE!$D$8*0.1*0.15 -> 0 | F18: =SUM(C18:E18) -> 0 | G18: =G17+F18 -> 0
A19: Q4 FY28 | B19: Jan-Mar 2028 | C19: =SALES_REVENUE!$D$8*0.1*0.25 -> 0 | D19: =SALES_REVENUE!$D$8*0.1*0.60 -> 0 | E19: =SALES_REVENUE!$D$8*0.1*0.15 -> 0 | F19: =SUM(C19:E19) -> 0 | G19: =G18+F19 -> 0
A20: Q1 FY29 | B20: Apr-Jun 2028 | C20: =SALES_REVENUE!$D$8*0.1*0.25 -> 0 | D20: =SALES_REVENUE!$D$8*0.1*0.60 -> 0 | E20: =SALES_REVENUE!$D$8*0.1*0.15 -> 0 | F20: =SUM(C20:E20) -> 0 | G20: =G19+F20 -> 0
A21: Q2 FY29 | B21: Jul-Sep 2028 | C21: =SALES_REVENUE!$D$8*0.06*0.25 -> 0 | D21: =SALES_REVENUE!$D$8*0.06*0.60 -> 0 | E21: =SALES_REVENUE!$D$8*0.06*0.15 -> 0 | F21: =SUM(C21:E21) -> 0 | G21: =G20+F21 -> 0

Sheet CASH_FLOW
A1: QUARTERLY CASH FLOW WATERFALL - ROI / IRR / MOIC
A3: Quarter | B3: Date | C3: Revenue Inflow | D3: Land Cost | E3: Construction | F3: Permits | G3: SG&A | H3: Debt Drawdown | I3: Debt Service | J3: Net Cash Flow | K3: Cumulative CF
A4: Q1 FY27 | B4: 46203 | C4: =SALES_REVENUE!F12 -> 0 | D4: =ASSUMPTIONS!$B$13*0.5 -> 0 | E4: =(ASSUMPTIONS!$B$16+ASSUMPTIONS!$B$18)*0.02 -> 0 | F4: =ASSUMPTIONS!$B$21*0.2 -> 0 | G4: =C4*ASSUMPTIONS!$B$50 -> 0 | H4: =ASSUMPTIONS!$B$60*0.05 -> 0 | I4: =ASSUMPTIONS!$B$60*ASSUMPTIONS!$B$46/4*0 -> 0 | J4: =C4+H4-D4-E4-F4-G4-I4 -> 0 | K4: =J4 -> 0
A5: Q2 FY27 | B5: 46295 | C5: =SALES_REVENUE!F13 -> 0 | D5: =ASSUMPTIONS!$B$13*0.3 -> 0 | E5: =(ASSUMPTIONS!$B$16+ASSUMPTIONS!$B$18)*0.05 -> 0 | F5: =ASSUMPTIONS!$B$21*0.25 -> 0 | G5: =C5*ASSUMPTIONS!$B$50 -> 0 | H5: =ASSUMPTIONS!$B$60*0.1 -> 0 | I5: =ASSUMPTIONS!$B$60*ASSUMPTIONS!$B$46/4*0 -> 0 | J5: =C5+H5-D5-E5-F5-G5-I5 -> 0 | K5: =K4+J5 -> 0
A6: Q3 FY27 | B6: 46387 | C6: =SALES_REVENUE!F14 -> 0 | D6: =ASSUMPTIONS!$B$13*0.1 -> 0 | E6: =(ASSUMPTIONS!$B$16+ASSUMPTIONS!$B$18)*0.08 -> 0 | F6: =ASSUMPTIONS!$B$21*0.2 -> 0 | G6: =C6*ASSUMPTIONS!$B$50 -> 0 | H6: =ASSUMPTIONS!$B$60*0.12 -> 0 | I6: =ASSUMPTIONS!$B$60*ASSUMPTIONS!$B$46/4*0 -> 0 | J6: =C6+H6-D6-E6-F6-G6-I6 -> 0 | K6: =K5+J6 -> 0
A7: Q4 FY27 | B7: 46477 | C7: =SALES_REVENUE!F15 -> 0 | D7: =ASSUMPTIONS!$B$13*0.05 -> 0 | E7: =(ASSUMPTIONS!$B$16+ASSUMPTIONS!$B$18)*0.1 -> 0 | F7: =ASSUMPTIONS!$B$21*0.15 -> 0 | G7: =C7*ASSUMPTIONS!$B$50 -> 0 | H7: =ASSUMPTIONS!$B$60*0.13 -> 0 | I7: =ASSUMPTIONS!$B$60*ASSUMPTIONS!$B$46/4*0 -> 0 | J7: =C7+H7-D7-E7-F7-G7-I7 -> 0 | K7: =K6+J7 -> 0
A8: Q1 FY28 | B8: 46568 | C8: =SALES_REVENUE!F16 -> 0 | D8: =ASSUMPTIONS!$B$13*0.05 -> 0 | E8: =(ASSUMPTIONS!$B$16+ASSUMPTIONS!$B$18)*0.12 -> 0 | F8: =ASSUMPTIONS!$B$21*0.1 -> 0 | G8: =C8*ASSUMPTIONS!$B$50 -> 0 | H8: =ASSUMPTIONS!$B$60*0.15 -> 0 | I8: =ASSUMPTIONS!$B$60*ASSUMPTIONS!$B$46/4*0 -> 0 | J8: =C8+H8-D8-E8-F8-G8-I8 -> 0 | K8: =K7+J8 -> 0
A9: Q2 FY28 | B9: 46660 | C9: =SALES_REVENUE!F17 -> 0 | D9: =ASSUMPTIONS!$B$13*0 -> 0 | E9: =(ASSUMPTIONS!$B$16+ASSUMPTIONS!$B$18)*0.15 -> 0 | F9: =ASSUMPTIONS!$B$21*0.05 -> 0 | G9: =C9*ASSUMPTIONS!$B$50 -> 0 | H9: =ASSUMPTIONS!$B$60*0.15 -> 0 | I9: =ASSUMPTIONS!$B$60*ASSUMPTIONS!$B$46/4*0.1 -> 0 | J9: =C9+H9-D9-E9-F9-G9-I9 -> 0 | K9: =K8+J9 -> 0
A10: Q3 FY28 | B10: 46752 | C10: =SALES_REVENUE!F18 -> 0 | D10: =ASSUMPTIONS!$B$13*0 -> 0 | E10: =(ASSUMPTIONS!$B$16+ASSUMPTIONS!$B$18)*0.15 -> 0 | F10: =ASSUMPTIONS!$B$21*0.05 -> 0 | G10: =C10*ASSUMPTIONS!$B$50 -> 0 | H10: =ASSUMPTIONS!$B$60*0.12 -> 0 | I10: =ASSUMPTIONS!$B$60*ASSUMPTIONS!$B$46/4*0.15 -> 0 | J10: =C10+H10-D10-E10-F10-G10-I10 -> 0 | K10: =K9+J10 -> 0
A11: Q4 FY28 | B11: 46843 | C11: =SALES_REVENUE!F19 -> 0 | D11: =ASSUMPTIONS!$B$13*0 -> 0 | E11: =(ASSUMPTIONS!$B$16+ASSUMPTIONS!$B$18)*0.13 -> 0 | F11: =ASSUMPTIONS!$B$21*0 -> 0 | G11: =C11*ASSUMPTIONS!$B$50 -> 0 | H11: =ASSUMPTIONS!$B$60*0.1 -> 0 | I11: =ASSUMPTIONS!$B$60*ASSUMPTIONS!$B$46/4*0.2 -> 0 | J11: =C11+H11-D11-E11-F11-G11-I11 -> 0 | K11: =K10+J11 -> 0
A12: Q1 FY29 | B12: 46934 | C12: =SALES_REVENUE!F20 -> 0 | D12: =ASSUMPTIONS!$B$13*0 -> 0 | E12: =(ASSUMPTIONS!$B$16+ASSUMPTIONS!$B$18)*0.12 -> 0 | F12: =ASSUMPTIONS!$B$21*0 -> 0 | G12: =C12*ASSUMPTIONS!$B$50 -> 0 | H12: =ASSUMPTIONS!$B$60*0.05 -> 0 | I12: =ASSUMPTIONS!$B$60*ASSUMPTIONS!$B$46/4*0.3 -> 0 | J12: =C12+H12-D12-E12-F12-G12-I12 -> 0 | K12: =K11+J12 -> 0
A13: Q2 FY29 | B13: 47026 | C13: =SALES_REVENUE!F21 -> 0 | D13: =ASSUMPTIONS!$B$13*0 -> 0 | E13: =(ASSUMPTIONS!$B$16+ASSUMPTIONS!$B$18)*0.08 -> 0 | F13: =ASSUMPTIONS!$B$21*0 -> 0 | G13: =C13*ASSUMPTIONS!$B$50 -> 0 | H13: =ASSUMPTIONS!$B$60*0.03 -> 0 | I13: =ASSUMPTIONS!$B$60*ASSUMPTIONS!$B$46/4*0.25 -> 0 | J13: =C13+H13-D13-E13-F13-G13-I13 -> 0 | K13: =K12+J13 -> 0
A16: RETURNS METRICS
A17: Total Revenue | B17: =SUM(C4:C13) -> 0
A18: Total Project Cost | B18: =ASSUMPTIONS!$B$59 -> 0
A19: Net Profit | B19: =ASSUMPTIONS!$B$62 -> 0
A20: ROI (%) | B20: =ASSUMPTIONS!$B$62/ASSUMPTIONS!$B$59 -> 0
A21: MOIC | B21: =SALES_REVENUE!$D$8/ASSUMPTIONS!$B$59 -> 0
A22: IRR (XIRR) | B22: =XIRR(J4:J13,B4:B13) -> 0
A23: NPV | B23: =NPV(ASSUMPTIONS!$B$52,J4:J13) -> 0
A24: DSCR (avg) | B24: =AVERAGE(IF(I4:I13=0,0,(C4:C13-G4:G13)/I4:I13)) -> 0
A25: LTV | B25: =ASSUMPTIONS!$B$60/SALES_REVENUE!$D$8 -> 0

Sheet CEO_CFO_REPORT
A1: CEO & CFO EXECUTIVE SUMMARY REPORT
A2: Villa Construction Financial Model | Hyderabad, Telangana
A5: PROJECT SNAPSHOT
A6: Item | B6: Value
A7: Project | B7: 50 Luxury Villas - 3 Floors Each
A8: Location | B8: Hyderabad, Telangana
A9: Duration | B9: 30 Months (Apr 2026 - Sep 2028)
A10: Total Built-up | B10: =ASSUMPTIONS!$B$8&" sq.ft" -> 0
A11: Total Villas | B11: =ASSUMPTIONS!$B$5 -> 0
A13: FINANCIAL HIGHLIGHTS
A14: Item | B14: Value
A15: Total Revenue | B15: =SALES_REVENUE!$D$8 -> 0
A16: Total Project Cost | B16: =ASSUMPTIONS!$B$59 -> 0
A17: Land Cost | B17: =ASSUMPTIONS!$B$13 -> 0
A18: Construction Cost | B18: =ASSUMPTIONS!$B$16 -> 0
A19: Contingency | B19: =ASSUMPTIONS!$B$18 -> 0
A20: Permits & Approvals | B20: =PERMITS!$B$21 -> 0
A21: Net Profit (after tax) | B21: =ASSUMPTIONS!$B$62 -> 0
A23: RETURNS ANALYSIS
A24: Item | B24: Value
A25: ROI | B25: =CASH_FLOW!$B$19 -> 0
A26: IRR (XIRR) | B26: =CASH_FLOW!$B$21 -> 0
A27: MOIC | B27: =CASH_FLOW!$B$20 -> 0
A28: NPV @ Discount Rate | B28: =CASH_FLOW!$B$22 -> 0
A29: DSCR (Average) | B29: =CASH_FLOW!$B$23 -> 0
A30: LTV Ratio | B30: =CASH_FLOW!$B$24 -> 0
A32: FINANCING STRUCTURE
A33: Item | B33: Value
A34: Total Debt | B34: =ASSUMPTIONS!$B$60 -> 0
A35: Equity | B35: =ASSUMPTIONS!$B$61 -> 0
A36: Debt / Equity Ratio | B36: =ASSUMPTIONS!$B$60/ASSUMPTIONS!$B$61 -> 0
A37: Interest Rate | B37: =ASSUMPTIONS!$B$46 -> 0
A38: Loan Tenor | B38: =ASSUMPTIONS!$B$47&" years" -> 0
A40: PERMITS STATUS (TSSPDCL / GHMC / RERA)
A41: Item | B41: Value
A42: GHMC Building Permission | B42: =PERMITS!$E$4 -> 0
A43: RERA Registration | B43: =PERMITS!$E$5 -> 0
A44: Fire NOC | B44: =PERMITS!$E$6 -> 0
A45: TSSPDCL Electricity (LT) | B45: =PERMITS!$E$7 -> 0
A46: TSSPDCL Electricity (HT) | B46: =PERMITS!$E$8 -> 0
...
